# raise-TypeError-r-is-a-built-in-class-.format-object-
Downloading and preparing dataset csiq/1.0.0 (download: Unknown size, generated: Unknown size, total: Unknown size) to C:\Users\Kamal\tensorflow_datasets\csiq\1.0.0... --------------------------------------------------------------------------- TypeError                                 Traceback (most recent call last) &lt;ipython-input-27-f3d8fdedd63c> in &lt;module>       1 builder = csiq() ----> 2 builder.download_and_prepare(download_dir=None, download_config=None)       3 ds = builder.as_dataset(shuffle_files=True)['train']       4 #train_ds, test_ds = builder.as_dataset(split=['train[:80%]', 'train[-20%:]'],shuffle_files=True) #['First 80% train', ' last       5 train_ds = ds.shuffle(250).batch(1)  ~\anaconda3\envs\kamal\lib\site-packages\tensorflow_datasets\core\dataset_builder.py in download_and_prepare(self, download_dir, download_config)     385     self._log_download_bytes()     386  --> 387     dl_manager = self._make_download_manager(     388         download_dir=download_dir,     389         download_config=download_config)  ~\anaconda3\envs\kamal\lib\site-packages\tensorflow_datasets\core\dataset_builder.py in _make_download_manager(self, download_dir, download_config)     818         extract_dir=extract_dir,     819         manual_dir=manual_dir, --> 820         url_infos=self.url_infos,     821         manual_dir_instructions=self.MANUAL_DOWNLOAD_INSTRUCTIONS,     822         force_download=(download_config.download_mode == FORCE_REDOWNLOAD),  ~\anaconda3\envs\kamal\lib\site-packages\tensorflow_datasets\core\utils\py_utils.py in __get__(self, obj, objtype)     130      131   def __get__(self, obj, objtype=None): --> 132     return self.fget.__get__(None, objtype)()  # pytype: disable=attribute-error     133      134   ~\anaconda3\envs\kamal\lib\site-packages\tensorflow_datasets\core\dataset_builder.py in url_infos(cls)     283      284     # Search for the url_info file. --> 285     checksums_path = cls._checksums_path     286     # If url_info file is found, load the urls     287     if checksums_path.exists():  ~\anaconda3\envs\kamal\lib\site-packages\tensorflow_datasets\core\utils\py_utils.py in __get__(self, obj, objtype)     130      131   def __get__(self, obj, objtype=None): --> 132     return self.fget.__get__(None, objtype)()  # pytype: disable=attribute-error     133      134   ~\anaconda3\envs\kamal\lib\site-packages\tensorflow_datasets\core\dataset_builder.py in _checksums_path(cls)     272     # * To load the checksums (in url_infos)     273     # * To save the checksums (in DownloadManager) --> 274     return cls.code_path.parent / "checksums.tsv"     275      276   @utils.classproperty  ~\anaconda3\envs\kamal\lib\site-packages\tensorflow_datasets\core\utils\py_utils.py in __get__(self, obj, objtype)     130      131   def __get__(self, obj, objtype=None): --> 132     return self.fget.__get__(None, objtype)()  # pytype: disable=attribute-error     133      134   ~\anaconda3\envs\kamal\lib\site-packages\tensorflow_datasets\core\dataset_builder.py in code_path(cls)     204     # Otherwise, fallback to `pathlib.Path`. For non-zipapp, it should be     205     # equivalent to the above return. --> 206     return utils.as_path(inspect.getfile(cls))     207      208   def __getstate__(self):  ~\anaconda3\envs\kamal\lib\inspect.py in getfile(object)     663             if getattr(module, '__file__', None):     664                 return module.__file__ --> 665         raise TypeError('{!r} is a built-in class'.format(object))     666     if ismethod(object):     667         object = object.__func__  TypeError: &lt;class '__main__.csiq'> is a built-in class
